<?xml version="1.0" encoding="utf-8"?>
<!-- This URDF was automatically created by SolidWorks to URDF Exporter! Originally created by Stephen Brawner (brawner@gmail.com) 
     Commit Version: 1.6.0-4-g7f85cfe  Build Version: 1.6.7995.38578
     For more information, please see http://wiki.ros.org/sw_urdf_exporter -->
<robot name="ASS_Robot" xmlns:xacro="http://www.ros.org/wiki/xacro">
<xacro:include filename="$(find mobile_robot)/model/ass_robot_description/urdf/robot.gazebo"/>
  <link
    name="base_link">
    <inertial>
      <origin
        xyz="0.0150421058918037 7.87415460802576E-06 -0.0694802702894512"
        rpy="0 0 0" />
      <mass
        value="28.8218329453164" />
      <inertia
        ixx="0.487581987962772"
        ixy="2.6462409224555E-05"
        ixz="0.00273098857312145"
        iyy="0.550268443099047"
        iyz="1.05480606357733E-06"
        izz="0.924041089909813" />
    </inertial>
    <visual>
      <origin
        xyz="0 0 0"
        rpy="0 0 0" />
      <geometry>
        <mesh
          filename="package://ass_robot_description/meshes/base_link.STL" />
      </geometry>
      <material
        name="">
        <color
          rgba="0.792156862745098 0.819607843137255 0.933333333333333 1" />
      </material>
    </visual>
    <collision>
      <origin xyz="0.05 0 -0.07" rpy="0 0 0" />
      <geometry>
        <box size="0.40 0.45 0.15"/>
      </geometry>
    </collision>
  </link>
  <link
    name="Left_wheel">
    <inertial>
      <origin
        xyz="0 0 -0.0387"
        rpy="0 0 0" />
      <mass
        value="1.17320543741845" />
      <inertia
        ixx="0.00198800277932776"
        ixy="0"
        ixz="0"
        iyy="0.00198800277932776"
        iyz="0"
        izz="0.00283501232765337" />
    </inertial>
    <visual>
      <origin
        xyz="0 0 0"
        rpy="0 -0.22305 0" />
      <geometry>
        <mesh
          filename="package://ass_robot_description/meshes/Left_wheel.STL" />
      </geometry>
      <material
        name="">
        <color
          rgba="0.752941176470588 0.752941176470588 0.752941176470588 1" />
      </material>
    </visual>
    <collision>
      <origin
        xyz="0 0 0"
        rpy="0 0 0" />
      <geometry>
        <cylinder radius="0.0695" length="0.05"/>
      </geometry>
    </collision>
  </link>
  <joint
    name="left_wheel_joint"
    type="continuous">
    <origin
      xyz="-0.073544 0.24905 -0.1"
      rpy="-1.5708 0 0" />
    <parent
      link="base_link" />
    <child
      link="Left_wheel" />
    <axis
      xyz="0 0 1" />
    <dynamics
      damping="0.1"
      friction="0.1" />
  </joint>
  <link
    name="Right_wheel">
    <inertial>
      <origin
        xyz="5.55111512312578E-17 0 0.0387"
        rpy="0 0 0" />
      <mass
        value="1.17320543741845" />
      <inertia
        ixx="0.00198800277932776"
        ixy="4.06575814682064E-19"
        ixz="2.98155597433514E-19"
        iyy="0.00198800277932776"
        iyz="-2.71050543121376E-19"
        izz="0.00283501232765337" />
    </inertial>
    <visual>
      <origin
        xyz="0 0 0"
        rpy="0 0 0" />
      <geometry>
        <mesh
          filename="package://ass_robot_description/meshes/Right_wheel.STL" />
      </geometry>
      <material
        name="">
        <color
          rgba="0.752941176470588 0.752941176470588 0.752941176470588 1" />
      </material>
    </visual>
    <collision>
      <origin
        xyz="0 0 0"
        rpy="0 0 0" />
      <geometry>
        <cylinder radius="0.0695" length="0.05"/>
      </geometry>
    </collision>
  </link>
  <joint
    name="right_wheel_joint"
    type="continuous">
    <origin
      xyz="-0.073544 -0.24905 -0.1"
      rpy="-1.5708 0 0" />
    <parent
      link="base_link" />
    <child
      link="Right_wheel" />
    <axis
      xyz="0 0 1" />
    <dynamics
      damping="0.1"
      friction="0.1" />
  </joint>
  <link
    name="Castor">
    <inertial>
      <origin
        xyz="-0.018216784333907 6.12481405370957E-07 -0.0496394726797626"
        rpy="0 0 0" />
      <mass
        value="0.0502982220794987" />
      <inertia
        ixx="2.10211254580428E-05"
        ixy="-7.4788853076431E-10"
        ixz="-3.69383064162082E-06"
        iyy="2.72371977958679E-05"
        iyz="-1.54428723768098E-09"
        izz="2.27374613649264E-05" />
    </inertial>
    <visual>
      <origin
        xyz="0 0 0"
        rpy="0 0 0" />
      <geometry>
        <mesh
          filename="package://ass_robot_description/meshes/Castor.STL" />
      </geometry>
      <material
        name="">
        <color
          rgba="0.792156862745098 0.819607843137255 0.933333333333333 1" />
      </material>
    </visual>
    <collision>
      <origin xyz="-0.018 0 -0.025" rpy="0 0 0" />
      <geometry>
        <box size="0.06 0.04 0.05"/>
      </geometry>
    </collision>
  </link>
  <joint
    name="Castor_joint"
    type="continuous">
    <origin
      xyz="0.18479 0 -0.0752"
      rpy="0 0 0" />
    <parent
      link="base_link" />
    <child
      link="Castor" />
    <axis
      xyz="0 0 1" />
  </joint>
  <link
    name="Castor_Wheel">
    <inertial>
      <origin
        xyz="0 0 0"
        rpy="0 0 0" />
      <mass
        value="0.0467334599376183" />
      <inertia
        ixx="1.04416967249263E-05"
        ixy="3.17637355220363E-22"
        ixz="1.05879118406788E-21"
        iyy="1.04416967249263E-05"
        iyz="1.27054942088145E-21"
        izz="1.49696419566983E-05" />
    </inertial>
    <visual>
      <origin
        xyz="0 0 0"
        rpy="0 0 0" />
      <geometry>
        <mesh
          filename="package://ass_robot_description/meshes/Castor_Wheel.STL" />
      </geometry>
      <material
        name="">
        <color
          rgba="0.752941176470588 0.752941176470588 0.752941176470588 1" />
      </material>
    </visual>
    <collision>
      <origin xyz="0 0 0" rpy="0 0 0" />
      <geometry>
        <sphere radius="0.025"/>
      </geometry>
    </collision>
  </link>
  <joint
    name="Castor_WheelLink"
    type="continuous">
    <origin
      xyz="-0.02 0 -0.0698"
      rpy="-1.5708 0 0" />
    <parent
      link="Castor" />
    <child
      link="Castor_Wheel" />
    <axis
      xyz="0 0 -1" />
    <dynamics
      damping="0.1"
      friction="0.1" />
  </joint>
  <link
    name="Upper_Swivel">
    <inertial>
      <origin
        xyz="-0.0134627540582945 0.00596515391221672 -0.35"
        rpy="0 0 0" />
      <mass
        value="27.6853568389625" />
      <inertia
        ixx="0.497938899929684"
        ixy="-0.0322428511237002"
        ixz="-0.00513742129672784"
        iyy="0.439455532873779"
        iyz="0.00227654026623388"
        izz="0.820571076943156" />
    </inertial>
    <visual>
      <origin
        xyz="0 0 0"
        rpy="0 0 0" />
      <geometry>
        <mesh
          filename="package://ass_robot_description/meshes/Upper_Swivel.STL" />
      </geometry>
      <material
        name="">
        <color
          rgba="0.792156862745098 0.819607843137255 0.933333333333333 1" />
      </material>
    </visual>
    <collision>
      <origin xyz="-0.013 0.006 0.077" rpy="0 0 0" />
      <geometry>
        <box size="0.40 0.40 0.30"/>
      </geometry>
    </collision>
  </link>
  <joint
    name="Upper_swivel"
    type="continuous">
    <origin
      xyz="0.0232320933885067 0 0.0100000000000001"
      rpy="0 0 0" />
    <parent
      link="base_link" />
    <child
      link="Upper_Swivel" />
    <axis
      xyz="0 0 1" />
    <dynamics
      damping="5.0"
      friction="2.0" />
  </joint>

  <link name="lidar_link">
    <inertial>
      <mass value="0.1"/>
      <inertia ixx="1e-5" ixy="0" ixz="0" iyy="1e-5" iyz="0" izz="1e-5"/>
    </inertial>
    <visual>
      <geometry>
        <cylinder radius="0.05" length="0.04"/>
      </geometry>
      <material name="">
        <color rgba="0.2 0.2 0.2 1"/>
      </material>
    </visual>
    <collision>
      <geometry>
        <cylinder radius="0.05" length="0.04"/>
      </geometry>
    </collision>
  </link>

  <ros2_control name="GazeboSystem" type="system">
    <hardware>
      <plugin>gz_ros2_control/GazeboSimSystem</plugin>
    </hardware>
    <joint name="Upper_swivel">
      <command_interface name="velocity"/>
      <state_interface name="position"/>
      <state_interface name="velocity"/>
    </joint>
  </ros2_control>

  <joint name="lidar_joint" type="fixed">
    <parent link="Upper_Swivel"/>
    <child link="lidar_link"/>
    <origin xyz="0 0 0.17" rpy="0 0 0"/>
  </joint>

</robot>